<?xml version="1.0" encoding="utf-8"?>

<!-- =================================================================================== -->
<!-- |    @uthor Min Htet Han ( ROM Robotics )                                         | -->
<!-- |    ROS Simulation Online Course                                                 | -->
<!-- =================================================================================== -->

<robot name="six_dof_arm">
  <link name="base_frame">
    <inertial>
      <mass value="359.99"/>
      <origin rpy="0 0 0" xyz="0 0 0"/>
      <inertia ixx="32.7" ixy="-7.3275e-15" ixz="-7.4508e-18" iyy="32.7" iyz="2.9965e-16" izz="60"/>
    </inertial>
    <collision>
      <origin rpy="0 0 0" xyz="0 0 0"/>
      <geometry>
        <box size="0.5 0.5 0.15"/>
      </geometry>
    </collision>
    <visual>
      <origin rpy="0 0 0" xyz="0 0 0"/>
      <geometry>
        <box size="0.5 0.5 0.15"/>
      </geometry>
    </visual>
  </link>
  <joint name="joint_one" type="revolute">
    <axis xyz="0 0 1"/>
    <limit effort="200" lower="-3.14" upper="3.14" velocity="0.2"/>
    <origin rpy="0 0 0" xyz="0 0 0.075"/>
    <parent link="base_frame"/>
    <child link="link_one"/>
  </joint>
  <transmission name="trans_joint_one">
    <type>transmission_interface/SimpleTransmission</type>
    <joint name="joint_one">
      <hardwareInterface>hardware_interface/EffortJointInterface</hardwareInterface>
    </joint>
    <actuator name="motor_joint_one">
      <hardwareInterface>hardware_interface/EffortJointInterface</hardwareInterface>
      <mechanicalReduction>1</mechanicalReduction>
    </actuator>
  </transmission>
  <link name="link_one">
    <inertial>
      <mass value="4.6167"/>
      <origin rpy="0 0 0" xyz="0 0 0"/>
      <inertia ixx="0.069637" ixy="-1.8435e-05" ixz="-1.1246e-05" iyy="0.069576" iyz="-0.0059016" izz="0.017056"/>
    </inertial>
    <collision>
      <origin rpy="0 0 0" xyz="0 0 0"/>
      <geometry>
        <mesh filename="package://urdf_tutorials/meshes/6dof/link_one.STL" scale="1 1 1"/>
      </geometry>
    </collision>
    <visual>
      <origin rpy="0 0 0" xyz="0 0 0"/>
      <geometry>
        <mesh filename="package://urdf_tutorials/meshes/6dof/link_one.STL" scale="1 1 1"/>
      </geometry>
      <material name="light_black"/>
    </visual>
  </link>
  <joint name="joint_two" type="revolute">
    <axis xyz="0 1 0"/>
    <limit effort="200" lower="-3.14" upper="3.14" velocity="0.2"/>
    <origin rpy="0 0 0" xyz="0 0 0.3048"/>
    <parent link="link_one"/>
    <child link="link_two"/>
  </joint>
  <transmission name="trans_joint_two">
    <type>transmission_interface/SimpleTransmission</type>
    <joint name="joint_two">
      <hardwareInterface>hardware_interface/EffortJointInterface</hardwareInterface>
    </joint>
    <actuator name="motor_joint_two">
      <hardwareInterface>hardware_interface/EffortJointInterface</hardwareInterface>
      <mechanicalReduction>1</mechanicalReduction>
    </actuator>
  </transmission>
  <link name="link_two">
    <inertial>
      <mass value="8.6679"/>
      <origin rpy="0 0 0" xyz="0 0 0"/>
      <inertia ixx="0.15166" ixy="3.6507e-08" ixz="-2.2357e-07" iyy="0.15385" iyz="1.0954e-07" izz="0.019839"/>
    </inertial>
    <collision>
      <origin rpy="0 0 0" xyz="0 0 0"/>
      <geometry>
        <mesh filename="package://urdf_tutorials/meshes/6dof/link_two.STL" scale="1 1 1"/>
      </geometry>
    </collision>
    <visual>
      <origin rpy="0 0 0" xyz="0 0 0"/>
      <geometry>
        <mesh filename="package://urdf_tutorials/meshes/6dof/link_two.STL" scale="1 1 1"/>
      </geometry>
      <material name="light_black"/>
    </visual>
  </link>
  <joint name="joint_three" type="revolute">
    <axis xyz="0 1 0"/>
    <limit effort="200" lower="-3.14" upper="3.14" velocity="0.2"/>
    <origin rpy="0 0 0" xyz="0 0 0.3302"/>
    <parent link="link_two"/>
    <child link="link_three"/>
  </joint>
  <transmission name="trans_joint_three">
    <type>transmission_interface/SimpleTransmission</type>
    <joint name="joint_three">
      <hardwareInterface>hardware_interface/EffortJointInterface</hardwareInterface>
    </joint>
    <actuator name="motor_joint_three">
      <hardwareInterface>hardware_interface/EffortJointInterface</hardwareInterface>
      <mechanicalReduction>1</mechanicalReduction>
    </actuator>
  </transmission>
  <link name="link_three">
    <inertial>
      <mass value="4.7843"/>
      <origin rpy="0 0 0" xyz="0 0 0"/>
      <inertia ixx="0.030521" ixy="1.0714e-09" ixz="-7.9633e-10" iyy="0.031396" iyz="0.005677" izz="0.010855"/>
    </inertial>
    <collision>
      <origin rpy="0 0 0" xyz="0 0 0"/>
      <geometry>
        <mesh filename="package://urdf_tutorials/meshes/6dof/link_three.STL" scale="1 1 1"/>
      </geometry>
    </collision>
    <visual>
      <origin rpy="0 0 0" xyz="0 0 0"/>
      <geometry>
        <mesh filename="package://urdf_tutorials/meshes/6dof/link_three.STL" scale="1 1 1"/>
      </geometry>
      <material name="light_black"/>
    </visual>
  </link>
  <joint name="joint_three_two" type="revolute">
    <axis xyz="0 0 1"/>
    <limit effort="200" lower="-3.14" upper="3.14" velocity="0.2"/>
    <origin rpy="0 0 0" xyz="0 0 0.1905"/>
    <parent link="link_three"/>
    <child link="link_three_two"/>
  </joint>
  <transmission name="trans_joint_three_two">
    <type>transmission_interface/SimpleTransmission</type>
    <joint name="joint_three_two">
      <hardwareInterface>hardware_interface/EffortJointInterface</hardwareInterface>
    </joint>
    <actuator name="motor_joint_three_two">
      <hardwareInterface>hardware_interface/EffortJointInterface</hardwareInterface>
      <mechanicalReduction>1</mechanicalReduction>
    </actuator>
  </transmission>
  <link name="link_three_two">
    <inertial>
      <mass value="4.7843"/>
      <origin rpy="0 0 0" xyz="0 0 0"/>
      <inertia ixx="0.030521" ixy="1.0714e-09" ixz="-7.9633e-10" iyy="0.031396" iyz="0.005677" izz="0.010855"/>
    </inertial>
    <collision>
      <origin rpy="0 0 0" xyz="0 0 0"/>
      <geometry>
        <mesh filename="package://urdf_tutorials/meshes/6dof/link_three_two.STL" scale="1 1 1"/>
      </geometry>
    </collision>
    <visual>
      <origin rpy="0 0 0" xyz="0 0 0"/>
      <geometry>
        <mesh filename="package://urdf_tutorials/meshes/6dof/link_three_two.STL" scale="1 1 1"/>
      </geometry>
      <material name="light_black"/>
    </visual>
  </link>
  <joint name="joint_four" type="revolute">
    <axis xyz="0 1 0"/>
    <limit effort="200" lower="-3.14" upper="3.14" velocity="0.2"/>
    <origin rpy="0 0 0" xyz="0 0 0.1905"/>
    <parent link="link_three_two"/>
    <child link="link_four"/>
  </joint>
  <transmission name="trans_joint_four">
    <type>transmission_interface/SimpleTransmission</type>
    <joint name="joint_four">
      <hardwareInterface>hardware_interface/EffortJointInterface</hardwareInterface>
    </joint>
    <actuator name="motor_joint_four">
      <hardwareInterface>hardware_interface/EffortJointInterface</hardwareInterface>
      <mechanicalReduction>1</mechanicalReduction>
    </actuator>
  </transmission>
  <link name="link_four">
    <inertial>
      <mass value="3.23"/>
      <origin rpy="0 0 0" xyz="0 0 0"/>
      <inertia ixx="0.011615" ixy="3.0049e-09" ixz="-2.3516e-09" iyy="0.013505" iyz="0.0016812" izz="0.0069931"/>
    </inertial>
    <collision>
      <origin rpy="0 0 0" xyz="0 0 0"/>
      <geometry>
        <mesh filename="package://urdf_tutorials/meshes/6dof/link_four.STL" scale="1 1 1"/>
      </geometry>
    </collision>
    <visual>
      <origin rpy="0 0 0" xyz="0 0 0"/>
      <geometry>
        <mesh filename="package://urdf_tutorials/meshes/6dof/link_four.STL" scale="1 1 1"/>
      </geometry>
      <material name="light_black"/>
    </visual>
  </link>
  <joint name="joint_five" type="revolute">
    <axis xyz="0 0 1"/>
    <limit effort="200" lower="-3.14" upper="3.14" velocity="0.2"/>
    <origin rpy="0 0 0" xyz="0 0 0.1143"/>
    <parent link="link_four"/>
    <child link="link_five"/>
  </joint>
  <transmission name="trans_joint_five">
    <type>transmission_interface/SimpleTransmission</type>
    <joint name="joint_five">
      <hardwareInterface>hardware_interface/EffortJointInterface</hardwareInterface>
    </joint>
    <actuator name="motor_joint_five">
      <hardwareInterface>hardware_interface/EffortJointInterface</hardwareInterface>
      <mechanicalReduction>1</mechanicalReduction>
    </actuator>
  </transmission>
  <link name="link_five">
    <inertial>
      <mass value="0.96751"/>
      <origin rpy="0 0 0" xyz="0 0 0"/>
      <inertia ixx="0.0012933" ixy="-1.7602e-11" ixz="-1.1137e-18" iyy="0.0013496" iyz="-1.4677e-18" izz="0.0024173"/>
    </inertial>
    <collision>
      <origin rpy="0 0 0" xyz="0 0 0"/>
      <geometry>
        <mesh filename="package://urdf_tutorials/meshes/6dof/link_five.STL" scale="1 1 1"/>
      </geometry>
    </collision>
    <visual>
      <origin rpy="0 0 0" xyz="0 0 0"/>
      <geometry>
        <mesh filename="package://urdf_tutorials/meshes/6dof/link_five.STL" scale="1 1 1"/>
      </geometry>
      <material name="light_black"/>
    </visual>
  </link>
  <joint name="gripper_one_joint" type="prismatic">
    <axis xyz="1 0 0"/>
    <limit effort="200" lower="0" upper="0.03" velocity="0.2"/>
    <origin rpy="0 0 0" xyz="-0.06 0 0.0881"/>
    <parent link="link_five"/>
    <child link="gripper_one"/>
  </joint>
  <transmission name="trans_gripper_one_joint">
    <type>transmission_interface/SimpleTransmission</type>
    <joint name="gripper_one_joint">
      <hardwareInterface>hardware_interface/EffortJointInterface</hardwareInterface>
    </joint>
    <actuator name="motor_gripper_one_joint">
      <hardwareInterface>hardware_interface/EffortJointInterface</hardwareInterface>
      <mechanicalReduction>1</mechanicalReduction>
    </actuator>
  </transmission>
  <link name="gripper_one">
    <inertial>
      <mass value="0.2"/>
      <origin rpy="0 0 0" xyz="0 0 0"/>
      <inertia ixx="0.0395416666667" ixy="0" ixz="0" iyy="0.106208333333" iyz="0" izz="0.106208333333"/>
    </inertial>
    <collision>
      <origin rpy="0 0 0" xyz="0 0 0"/>
      <geometry>
        <box size="0.01 0.05 0.1"/>
      </geometry>
    </collision>
    <visual>
      <origin rpy="0 0 0" xyz="0 0 0"/>
      <geometry>
        <box size="0.01 0.05 0.1"/>
      </geometry>
    </visual>
  </link>
  <joint name="gripper_two_joint" type="prismatic">
    <axis xyz="-1 0 0"/>
    <limit effort="200" lower="0" upper="0.03" velocity="0.2"/>
    <origin rpy="0 0 0" xyz="0.06 0 0.0881"/>
    <parent link="link_five"/>
    <child link="gripper_two"/>
  </joint>
  <transmission name="trans_gripper_two_joint">
    <type>transmission_interface/SimpleTransmission</type>
    <joint name="gripper_two_joint">
      <hardwareInterface>hardware_interface/EffortJointInterface</hardwareInterface>
    </joint>
    <actuator name="motor_gripper_two_joint">
      <hardwareInterface>hardware_interface/EffortJointInterface</hardwareInterface>
      <mechanicalReduction>1</mechanicalReduction>
    </actuator>
  </transmission>
  <link name="gripper_two">
    <inertial>
      <mass value="0.2"/>
      <origin rpy="0 0 0" xyz="0 0 0"/>
      <inertia ixx="0.0395416666667" ixy="0" ixz="0" iyy="0.106208333333" iyz="0" izz="0.106208333333"/>
    </inertial>
    <collision>
      <origin rpy="0 0 0" xyz="0 0 0"/>
      <geometry>
        <box size="0.01 0.05 0.1"/>
      </geometry>
    </collision>
    <visual>
      <origin rpy="0 0 0" xyz="0 0 0"/>
      <geometry>
        <box size="0.01 0.05 0.1"/>
      </geometry>
    </visual>
  </link>
  <gazebo>
    <plugin filename="libgazebo_ros_control.so" name="gazebo_ros_control">
      <robotNamespace>/six_dof_arm</robotNamespace>
    </plugin>
  </gazebo>
</robot>

